<?xml version="1.0"?>
<sdf version='1.6'>
  <world name='default'>
    <light name='sun' type='directional'>
      <cast_shadows>1</cast_shadows>
      <pose frame=''>0 0 10 0 -0 0</pose>
      <diffuse>0.8 0.8 0.8 1</diffuse>
      <specular>0.1 0.1 0.1 1</specular>
      <attenuation>
        <range>1000</range>
        <constant>0.9</constant>
        <linear>0.01</linear>
        <quadratic>0.001</quadratic>
      </attenuation>
      <direction>-0.5 0.5 -1</direction>
    </light>
    <model name='ground_plane'>
      <static>1</static>
      <link name='link'>
        <collision name='collision'>
          <geometry>
            <plane>
              <normal>0 0 1</normal>
              <size>100 100</size>
            </plane>
          </geometry>
          <surface>
            <friction>
              <ode>
                <mu>100</mu>
                <mu2>50</mu2>
              </ode>
              <torsional>
                <ode/>
              </torsional>
            </friction>
            <contact>
              <ode/>
            </contact>
            <bounce/>
          </surface>
          <max_contacts>10</max_contacts>
        </collision>
        <visual name='visual'>
          <cast_shadows>0</cast_shadows>
          <geometry>
            <plane>
              <normal>0 0 1</normal>
              <size>100 100</size>
            </plane>
          </geometry>
          <material>
            <script>
              <uri>file://media/materials/scripts/gazebo.material</uri>
              <name>Gazebo/Grey</name>
            </script>
          </material>
        </visual>
        <self_collide>0</self_collide>
        <kinematic>0</kinematic>
        <gravity>1</gravity>
      </link>
    </model>

    <physics name='default_physics' default='0' type='ode'>
      <ode>
        <solver>
          <type>quick</type>
          <iters>10</iters>
          <sor>1.3</sor>
          <use_dynamic_moi_rescaling>0</use_dynamic_moi_rescaling>
        </solver>
        <constraints>
          <cfm>0</cfm>
          <erp>0.2</erp>
          <contact_max_correcting_vel>100</contact_max_correcting_vel>
          <contact_surface_layer>0.001</contact_surface_layer>
        </constraints>
      </ode>
      <max_step_size>0.01</max_step_size>
      <real_time_factor>1</real_time_factor>
      <real_time_update_rate>500</real_time_update_rate>
    </physics>

	<model name='iris'>
		<link name='body'>
		  <pose frame=''>0 0 0 0 -0 0</pose>
		  <inertial>
			<pose frame=''>0 0 0 0 -0 0</pose>
			<mass>1.5</mass>
			<inertia>
			  <ixx>0.027125</ixx>
			  <iyy>0.027125</iyy>
			  <izz>0.054225</izz>
			  <ixy>0</ixy>
			  <ixz>0</ixz>
			  <iyz>0</iyz>
			</inertia>
		  </inertial>
		  <collision name='body_inertia_collision'>
			<pose frame=''>0 0 0 0 -0 0</pose>
			<geometry>
			  <box>
				<size>0.47 0.47 0.11</size>
			  </box>
			</geometry>
			<surface>
			  <contact>
				<ode>
				  <min_depth>0.001</min_depth>
				  <max_vel>0</max_vel>
				</ode>
			  </contact>
			  <friction>
				<ode/>
			  </friction>
			</surface>
		  </collision>
		  <visual name='body_inertia_visual'>
			<pose frame=''>0 0 0 0 -0 0</pose>
			<geometry>
			  <mesh>
				<scale>1 1 1</scale>
				<uri>model://rotors_description/meshes/iris.stl</uri>
			  </mesh>
			</geometry>
			<material>
			  <script>
				<name>Gazebo/DarkGrey</name>
				<uri>file://media/materials/scripts/gazebo.material</uri>
			  </script>
			</material>
		  </visual>
		  <gravity>1</gravity>
		  <velocity_decay/>
		</link>
		<link name='/imu_link'>
		  <pose frame=''>0 0 0 0 -0 0</pose>
		  <inertial>
			<pose frame=''>0 0 0 0 -0 0</pose>
			<mass>0.015</mass>
			<inertia>
			  <ixx>1e-05</ixx>
			  <ixy>0</ixy>
			  <ixz>0</ixz>
			  <iyy>1e-05</iyy>
			  <iyz>0</iyz>
			  <izz>1e-05</izz>
			</inertia>
		  </inertial>
		</link>
		<joint name='/imu_joint' type='revolute'>
		  <child>/imu_link</child>
		  <parent>body</parent>
		  <axis>
			<xyz>1 0 0</xyz>
			<limit>
			  <lower>0</lower>
			  <upper>0</upper>
			  <effort>0</effort>
			  <velocity>0</velocity>
			</limit>
			<dynamics>
			  <spring_reference>0</spring_reference>
			  <spring_stiffness>0</spring_stiffness>
			</dynamics>
			<use_parent_model_frame>1</use_parent_model_frame>
		  </axis>
		</joint>
		<link name='rotor_0'>
		  <pose frame=''>0.13 -0.22 0.023 0 -0 0</pose>
		  <inertial>
			<pose frame=''>0 0 0 0 -0 0</pose>
			<mass>0.005</mass>
			<inertia>
			  <ixx>9.75e-07</ixx>
			  <ixy>0</ixy>
			  <ixz>0</ixz>
			  <iyy>0.000273104</iyy>
			  <iyz>0</iyz>
			  <izz>0.000274004</izz>
			</inertia>
		  </inertial>
		  <collision name='rotor_0_collision'>
			<pose frame=''>0 0 0 0 -0 0</pose>
			<geometry>
			  <cylinder>
				<length>0.005</length>
				<radius>0.128</radius>
			  </cylinder>
			</geometry>
			<surface>
			  <contact>
				<ode/>
			  </contact>
			  <friction>
				<ode/>
			  </friction>
			</surface>
		  </collision>
		  <visual name='rotor_0_visual'>
			<pose frame=''>0 0 0 0 -0 0</pose>
			<geometry>
			  <mesh>
				<scale>1 1 1</scale>
				<uri>model://rotors_description/meshes/iris_prop_ccw.dae</uri>
			  </mesh>
			</geometry>
			<material>
			  <script>
				<name>Gazebo/Blue</name>
				<uri>file://media/materials/scripts/gazebo.material</uri>
			  </script>
			</material>
		  </visual>
		  <gravity>1</gravity>
		  <velocity_decay/>
		</link>
		<joint name='rotor_0_joint' type='revolute'>
		  <child>rotor_0</child>
		  <parent>body</parent>
		  <axis>
			<xyz>0 0 1</xyz>
			<limit>
			  <lower>-1e+16</lower>
			  <upper>1e+16</upper>
			</limit>
			<dynamics>
			  <spring_reference>0</spring_reference>
			  <spring_stiffness>0</spring_stiffness>
			</dynamics>
			<use_parent_model_frame>1</use_parent_model_frame>
		  </axis>
		</joint>
		<link name='rotor_1'>
		  <pose frame=''>-0.13 0.2 0.023 0 -0 0</pose>
		  <inertial>
			<pose frame=''>0 0 0 0 -0 0</pose>
			<mass>0.005</mass>
			<inertia>
			  <ixx>9.75e-07</ixx>
			  <ixy>0</ixy>
			  <ixz>0</ixz>
			  <iyy>0.000273104</iyy>
			  <iyz>0</iyz>
			  <izz>0.000274004</izz>
			</inertia>
		  </inertial>
		  <collision name='rotor_1_collision'>
			<pose frame=''>0 0 0 0 -0 0</pose>
			<geometry>
			  <cylinder>
				<length>0.005</length>
				<radius>0.128</radius>
			  </cylinder>
			</geometry>
			<surface>
			  <contact>
				<ode/>
			  </contact>
			  <friction>
				<ode/>
			  </friction>
			</surface>
		  </collision>
		  <visual name='rotor_1_visual'>
			<pose frame=''>0 0 0 0 -0 0</pose>
			<geometry>
			  <mesh>
				<scale>1 1 1</scale>
				<uri>model://rotors_description/meshes/iris_prop_ccw.dae</uri>
			  </mesh>
			</geometry>
			<material>
			  <script>
				<name>Gazebo/DarkGrey</name>
				<uri>file://media/materials/scripts/gazebo.material</uri>
			  </script>
			</material>
		  </visual>
		  <gravity>1</gravity>
		  <velocity_decay/>
		</link>
		<joint name='rotor_1_joint' type='revolute'>
		  <child>rotor_1</child>
		  <parent>body</parent>
		  <axis>
			<xyz>0 0 1</xyz>
			<limit>
			  <lower>-1e+16</lower>
			  <upper>1e+16</upper>
			</limit>
			<dynamics>
			  <spring_reference>0</spring_reference>
			  <spring_stiffness>0</spring_stiffness>
			</dynamics>
			<use_parent_model_frame>1</use_parent_model_frame>
		  </axis>
		</joint>
		<link name='rotor_2'>
		  <pose frame=''>0.13 0.22 0.023 0 -0 0</pose>
		  <inertial>
			<pose frame=''>0 0 0 0 -0 0</pose>
			<mass>0.005</mass>
			<inertia>
			  <ixx>9.75e-07</ixx>
			  <ixy>0</ixy>
			  <ixz>0</ixz>
			  <iyy>0.000273104</iyy>
			  <iyz>0</iyz>
			  <izz>0.000274004</izz>
			</inertia>
		  </inertial>
		  <collision name='rotor_2_collision'>
			<pose frame=''>0 0 0 0 -0 0</pose>
			<geometry>
			  <cylinder>
				<length>0.005</length>
				<radius>0.128</radius>
			  </cylinder>
			</geometry>
			<surface>
			  <contact>
				<ode/>
			  </contact>
			  <friction>
				<ode/>
			  </friction>
			</surface>
		  </collision>
		  <visual name='rotor_2_visual'>
			<pose frame=''>0 0 0 0 -0 0</pose>
			<geometry>
			  <mesh>
				<scale>1 1 1</scale>
				<uri>model://rotors_description/meshes/iris_prop_cw.dae</uri>
			  </mesh>
			</geometry>
			<material>
			  <script>
				<name>Gazebo/Blue</name>
				<uri>file://media/materials/scripts/gazebo.material</uri>
			  </script>
			</material>
		  </visual>
		  <gravity>1</gravity>
		  <velocity_decay/>
		</link>
		<joint name='rotor_2_joint' type='revolute'>
		  <child>rotor_2</child>
		  <parent>body</parent>
		  <axis>
			<xyz>0 0 1</xyz>
			<limit>
			  <lower>-1e+16</lower>
			  <upper>1e+16</upper>
			</limit>
			<dynamics>
			  <spring_reference>0</spring_reference>
			  <spring_stiffness>0</spring_stiffness>
			</dynamics>
			<use_parent_model_frame>1</use_parent_model_frame>
		  </axis>
		</joint>
		<link name='rotor_3'>
		  <pose frame=''>-0.13 -0.2 0.023 0 -0 0</pose>
		  <inertial>
			<pose frame=''>0 0 0 0 -0 0</pose>
			<mass>0.005</mass>
			<inertia>
			  <ixx>9.75e-07</ixx>
			  <ixy>0</ixy>
			  <ixz>0</ixz>
			  <iyy>0.000273104</iyy>
			  <iyz>0</iyz>
			  <izz>0.000274004</izz>
			</inertia>
		  </inertial>
		  <collision name='rotor_3_collision'>
			<pose frame=''>0 0 0 0 -0 0</pose>
			<geometry>
			  <cylinder>
				<length>0.005</length>
				<radius>0.128</radius>
			  </cylinder>
			</geometry>
			<surface>
			  <contact>
				<ode/>
			  </contact>
			  <friction>
				<ode/>
			  </friction>
			</surface>
		  </collision>
		  <visual name='rotor_3_visual'>
			<pose frame=''>0 0 0 0 -0 0</pose>
			<geometry>
			  <mesh>
				<scale>1 1 1</scale>
				<uri>model://rotors_description/meshes/iris_prop_cw.dae</uri>
			  </mesh>
			</geometry>
			<material>
			  <script>
				<name>Gazebo/DarkGrey</name>
				<uri>file://media/materials/scripts/gazebo.material</uri>
			  </script>
			</material>
		  </visual>
		  <gravity>1</gravity>
		  <velocity_decay/>
		</link>
		<joint name='rotor_3_joint' type='revolute'>
		  <child>rotor_3</child>
		  <parent>body</parent>
		  <axis>
			<xyz>0 0 1</xyz>
			<limit>
			  <lower>-1e+16</lower>
			  <upper>1e+16</upper>
			</limit>
			<dynamics>
			  <spring_reference>0</spring_reference>
			  <spring_stiffness>0</spring_stiffness>
			</dynamics>
			<use_parent_model_frame>1</use_parent_model_frame>
		  </axis>
		</joint>
	  </model>

    <plugin name="GazeboPlugin" filename="libGazeboCoSimPlugin.so"><portNumber>14581</portNumber></plugin>
  </world>
</sdf>
	


